<?xml version="1.0" encoding="utf-8"?>
<!-- This URDF was automatically created by SolidWorks to URDF Exporter! Originally created by Stephen Brawner (brawner@gmail.com)
     Commit Version: 1.6.0-4-g7f85cfe  Build Version: 1.6.7995.38578
     For more information, please see http://wiki.ros.org/sw_urdf_exporter -->
<robot
  name="arm.SLDASM">
  <link
    name="base_link">
    <inertial>
      <origin
        xyz="-0.0559381356520999 0.0290055398271713 0.271283561362411"
        rpy="0 0 0" />
      <mass
        value="0.235064989394271" />
      <inertia
        ixx="0.000270092559502218"
        ixy="4.06196531583323E-22"
        ixz="1.2646553039904E-07"
        iyy="0.000959261287268697"
        iyz="1.75867997782058E-07"
        izz="0.000699718413983908" />
    </inertial>
    <visual>
      <origin
        xyz="0 0 0"
        rpy="0 0 0" />
      <geometry>
        <mesh
          filename="package://arm.SLDASM/meshes/base_link.STL" />
      </geometry>
      <material
        name="">
        <color
          rgba="0.792156862745098 0.819607843137255 0.933333333333333 1" />
      </material>
    </visual>
    <collision>
      <origin
        xyz="0 0 0"
        rpy="0 0 0" />
      <geometry>
        <mesh
          filename="package://arm.SLDASM/meshes/base_link.STL" />
      </geometry>
    </collision>
  </link>
  <link
    name="arm_Link1">
    <inertial>
      <origin
        xyz="-0.000380580428849309 0.0184419486359683 -0.0022830303356034"
        rpy="0 0 0" />
      <mass
        value="0.0856139789103628" />
      <inertia
        ixx="4.13766069192451E-05"
        ixy="-4.27113489668865E-08"
        ixz="4.50738468151171E-07"
        iyy="8.07300469806336E-05"
        iyz="-1.73034809257344E-07"
        izz="4.24100687312836E-05" />
    </inertial>
    <visual>
      <origin
        xyz="0 0 0"
        rpy="0 0 0" />
      <geometry>
        <mesh
          filename="package://arm.SLDASM/meshes/arm_Link1.STL" />
      </geometry>
      <material
        name="">
        <color
          rgba="0.792156862745098 0.819607843137255 0.933333333333333 1" />
      </material>
    </visual>
    <collision>
      <origin
        xyz="0 0 0"
        rpy="0 0 0" />
      <geometry>
        <mesh
          filename="package://arm.SLDASM/meshes/arm_Link1.STL" />
      </geometry>
    </collision>
  </link>
  <joint
    name="arm_joint1"
    type="continuous">
    <origin
      xyz="-0.10713 -0.27 0.055092"
      rpy="1.5708 0 0.26475" />
    <parent
      link="base_link" />
    <child
      link="arm_Link1" />
    <axis
      xyz="0 -1 0" />
    <limit
      lower="-1.57"
      upper="1.57"
      effort="10"
      velocity="1" />
  </joint>
  <link
    name="arm_Link2">
    <inertial>
      <origin
        xyz="-0.00126271232811451 0.0504842264334693 -0.00769989863501888"
        rpy="0 0 0" />
      <mass
        value="0.0173145104443779" />
      <inertia
        ixx="1.50133500868196E-05"
        ixy="1.28588409443901E-07"
        ixz="-6.48611196630956E-10"
        iyy="9.87298114243785E-06"
        iyz="-1.03250375066677E-11"
        izz="6.93552159344797E-06" />
    </inertial>
    <visual>
      <origin
        xyz="0 0 0"
        rpy="0 0 0" />
      <geometry>
        <mesh
          filename="package://arm.SLDASM/meshes/arm_Link2.STL" />
      </geometry>
      <material
        name="">
        <color
          rgba="0.792156862745098 0.819607843137255 0.933333333333333 1" />
      </material>
    </visual>
    <collision>
      <origin
        xyz="0 0 0"
        rpy="0 0 0" />
      <geometry>
        <mesh
          filename="package://arm.SLDASM/meshes/arm_Link2.STL" />
      </geometry>
    </collision>
  </link>
  <joint
    name="arm_joint2"
    type="continuous">
    <origin
      xyz="0.0097086 0.03009 -0.0023964"
      rpy="-0.0047341 0.24187 -0.019756" />
    <parent
      link="arm_Link1" />
    <child
      link="arm_Link2" />
    <axis
      xyz="-8.0295E-05 0 -1" />
    <limit
      lower="-1.57"
      upper="1.57"
      effort="10"
      velocity="1" />
  </joint>
  <link
    name="arm_Link3">
    <inertial>
      <origin
        xyz="-7.59417371959392E-07 -0.0198009919668684 -0.00945781260201439"
        rpy="0 0 0" />
      <mass
        value="0.0469201885614541" />
      <inertia
        ixx="2.08213775143729E-05"
        ixy="-1.41213633506396E-11"
        ixz="-6.21443981321135E-10"
        iyy="1.13835679307676E-05"
        iyz="-1.75867997215178E-07"
        izz="1.30818905539686E-05" />
    </inertial>
    <visual>
      <origin
        xyz="0 0 0"
        rpy="0 0 0" />
      <geometry>
        <mesh
          filename="package://arm.SLDASM/meshes/arm_Link3.STL" />
      </geometry>
      <material
        name="">
        <color
          rgba="0.792156862745098 0.819607843137255 0.933333333333333 1" />
      </material>
    </visual>
    <collision>
      <origin
        xyz="0 0 0"
        rpy="0 0 0" />
      <geometry>
        <mesh
          filename="package://arm.SLDASM/meshes/arm_Link3.STL" />
      </geometry>
    </collision>
  </link>
  <joint
    name="arm_joint3"
    type="continuous">
    <origin
      xyz="-0.0025242 0.10097 0"
      rpy="0 -0.00016057 -3.1166" />
    <parent
      link="arm_Link2" />
    <child
      link="arm_Link3" />
    <axis
      xyz="-8.0295E-05 0 -1" />
    <limit
      lower="-1.57"
      upper="1.57"
      effort="10"
      velocity="1" />
  </joint>
  <link
    name="arm_Link4">
    <inertial>
      <origin
        xyz="-7.85495715305284E-07 0.0163736511886758 -0.00978259386825203"
        rpy="0 0 0" />
      <mass
        value="0.0765258666785306" />
      <inertia
        ixx="2.66261902408435E-05"
        ixy="-8.84438054553948E-20"
        ixz="-8.48188814758824E-10"
        iyy="1.60628144332821E-05"
        iyz="-1.17360385309024E-20"
        izz="1.60628145013875E-05" />
    </inertial>
    <visual>
      <origin
        xyz="0 0 0"
        rpy="0 0 0" />
      <geometry>
        <mesh
          filename="package://arm.SLDASM/meshes/arm_Link4.STL" />
      </geometry>
      <material
        name="">
        <color
          rgba="0.792156862745098 0.819607843137255 0.933333333333333 1" />
      </material>
    </visual>
    <collision>
      <origin
        xyz="0 0 0"
        rpy="0 0 0" />
      <geometry>
        <mesh
          filename="package://arm.SLDASM/meshes/arm_Link4.STL" />
      </geometry>
    </collision>
  </link>
  <joint
    name="arm_joint4"
    type="continuous">
    <origin
      xyz="0 -0.0915 0.00060959"
      rpy="0 -0.00016059 3.1416" />
    <parent
      link="arm_Link3" />
    <child
      link="arm_Link4" />
    <axis
      xyz="-8.0295E-05 0 -1" />
    <limit
      lower="-1.57"
      upper="1.57"
      effort="10"
      velocity="1" />
  </joint>
  <link
    name="gripper_Link">
    <inertial>
      <origin
        xyz="-0.0245680525776589 0.0274397194368598 -0.0222177482287967"
        rpy="0 0 0" />
      <mass
        value="0.0390911743102487" />
      <inertia
        ixx="7.40750989896945E-06"
        ixy="1.26780785874517E-12"
        ixz="-1.75989713502629E-07"
        iyy="9.89371312760785E-06"
        iyz="1.5710282247013E-08"
        izz="5.89164823044217E-06" />
    </inertial>
    <visual>
      <origin
        xyz="0 0 0"
        rpy="0 0 0" />
      <geometry>
        <mesh
          filename="package://arm.SLDASM/meshes/gripper_Link.STL" />
      </geometry>
      <material
        name="">
        <color
          rgba="0.792156862745098 0.819607843137255 0.933333333333333 1" />
      </material>
    </visual>
    <collision>
      <origin
        xyz="0 0 0"
        rpy="0 0 0" />
      <geometry>
        <mesh
          filename="package://arm.SLDASM/meshes/gripper_Link.STL" />
      </geometry>
    </collision>
  </link>
  <joint
    name="gripper_joint"
    type="continuous">
    <origin
      xyz="-0.0064346 0.066247 -0.021069"
      rpy="3.1416 0.40529 3.1416" />
    <parent
      link="arm_Link4" />
    <child
      link="gripper_Link" />
    <axis
      xyz="0 -1 0" />
    <limit
      lower="-1.57"
      upper="1.57"
      effort="10"
      velocity="1" />
  </joint>
  <link
    name="end_Link2">
    <inertial>
      <origin
        xyz="-0.0937628645641986 0.392527344713982 0.252157172838664"
        rpy="0 0 0" />
      <mass
        value="0.0055020160484979" />
      <inertia
        ixx="1.23367851048737E-06"
        ixy="-1.80685890155106E-11"
        ixz="-3.24139716279196E-11"
        iyy="4.2956025085267E-07"
        iyz="-2.24927161337994E-07"
        izz="8.29848844693928E-07" />
    </inertial>
    <visual>
      <origin
        xyz="0 0 0"
        rpy="0 0 0" />
      <geometry>
        <mesh
          filename="package://arm.SLDASM/meshes/end_Link2.STL" />
      </geometry>
      <material
        name="">
        <color
          rgba="0.792156862745098 0.819607843137255 0.933333333333333 1" />
      </material>
    </visual>
    <collision>
      <origin
        xyz="0 0 0"
        rpy="0 0 0" />
      <geometry>
        <mesh
          filename="package://arm.SLDASM/meshes/end_Link2.STL" />
      </geometry>
    </collision>
  </link>
  <joint
    name="end_joint2"
    type="fixed">
    <origin
      xyz="0.090025 -0.41139 -0.0025945"
      rpy="-0.51158 1.028E-05 3.9309E-05" />
    <parent
      link="gripper_Link" />
    <child
      link="end_Link2" />
    <axis
      xyz="0 0 0" />
    <limit
      lower="-1.57"
      upper="1.57"
      effort="10"
      velocity="1" />
  </joint>
  <link
    name="end_Link1">
    <inertial>
      <origin
        xyz="-0.00368912775195826 0.0298917848785729 0.00672175796450536"
        rpy="0 0 0" />
      <mass
        value="0.00527568125483211" />
      <inertia
        ixx="1.22637525120268E-06"
        ixy="-2.60880878100607E-11"
        ixz="-3.67120372105377E-11"
        iyy="4.82955625911365E-07"
        iyz="-3.25046161090952E-07"
        izz="7.68871854263911E-07" />
    </inertial>
    <visual>
      <origin
        xyz="0 0 0"
        rpy="0 0 0" />
      <geometry>
        <mesh
          filename="package://arm.SLDASM/meshes/end_Link1.STL" />
      </geometry>
      <material
        name="">
        <color
          rgba="0.792156862745098 0.819607843137255 0.933333333333333 1" />
      </material>
    </visual>
    <collision>
      <origin
        xyz="0 0 0"
        rpy="0 0 0" />
      <geometry>
        <mesh
          filename="package://arm.SLDASM/meshes/end_Link1.STL" />
      </geometry>
    </collision>
  </link>
  <joint
    name="end_joint1"
    type="continuous">
    <origin
      xyz="0 0.028663 -0.01525"
      rpy="-0.55028 1.1853E-05 4.1989E-05" />
    <parent
      link="gripper_Link" />
    <child
      link="end_Link1" />
    <axis
      xyz="1 4.5406E-05 -4.6232E-05" />
    <limit
      lower="-1.57"
      upper="1.57"
      effort="10"
      velocity="1" />
  </joint>
</robot>
